2019-07-16 16:17:19,360 - INFO -  * Running on http://0.0.0.0:8801/ (Press CTRL+C to quit)
2019-07-16 16:17:19,720 - DEBUG - ('SELECT `t1`.`deviceID`, `t1`.`name`, `t1`.`location`, `t1`.`latitude`, `t1`.`longitude`, `t1`.`customerOwner_id`, `t1`.`dataControllerPeriod`, `t1`.`commandControllerPeriod`, `t1`.`timeOfLastCheckIn`, `t1`.`missedCommands`, `t1`.`commandTimeWindow`, `t1`.`status` FROM `device` AS `t1` WHERE (`t1`.`deviceID` = %s) LIMIT %s OFFSET %s', [1, 1, 0])
2019-07-16 16:17:19,724 - DEBUG - Validate DID: DID '1' Validate
2019-07-16 16:17:19,725 - DEBUG - ('INSERT INTO `reliabledelivery` (`timeStamp`, `payload`, `sent`, `deviceOwner_id`) VALUES (%s, %s, %s, %s)', [datetime.datetime(2019, 7, 16, 22, 17, 14, 340671), "{'TEST': 12345}", False, 1])
2019-07-16 16:17:19,727 - DEBUG - Data Push Hit: New Entry Into RD
2019-07-16 16:17:19,728 - INFO - 127.0.0.1 - - [16/Jul/2019 16:17:19] "POST /device/dataPush HTTP/1.1" 200 -
2019-07-16 16:17:19,732 - INFO - Data Push Hit: No deviceID Provided
2019-07-16 16:17:19,733 - DEBUG - ('SELECT `t1`.`deviceID`, `t1`.`name`, `t1`.`location`, `t1`.`latitude`, `t1`.`longitude`, `t1`.`customerOwner_id`, `t1`.`dataControllerPeriod`, `t1`.`commandControllerPeriod`, `t1`.`timeOfLastCheckIn`, `t1`.`missedCommands`, `t1`.`commandTimeWindow`, `t1`.`status` FROM `device` AS `t1` WHERE (`t1`.`deviceID` IS %s) LIMIT %s OFFSET %s', [None, 1, 0])
2019-07-16 16:17:19,738 - WARNING - Validate DID: DID 'None' Failed Validation. Unknown Error.
Exception: <Model: Device> instance matching query does not exist:
SQL: SELECT `t1`.`deviceID`, `t1`.`name`, `t1`.`location`, `t1`.`latitude`, `t1`.`longitude`, `t1`.`customerOwner_id`, `t1`.`dataControllerPeriod`, `t1`.`commandControllerPeriod`, `t1`.`timeOfLastCheckIn`, `t1`.`missedCommands`, `t1`.`commandTimeWindow`, `t1`.`status` FROM `device` AS `t1` WHERE (`t1`.`deviceID` IS %s) LIMIT %s OFFSET %s
Params: [None, 1, 0]
TraceBack: Traceback (most recent call last):
  File "/Users/brendonstanley/virtual/Totality/lib/python3.7/site-packages/peewee.py", line 6496, in get
    return clone.execute(database)[0]
  File "/Users/brendonstanley/virtual/Totality/lib/python3.7/site-packages/peewee.py", line 4024, in __getitem__
    return self.row_cache[item]
IndexError: list index out of range

During handling of the above exception, another exception occurred:

Traceback (most recent call last):
  File "/Users/brendonstanley/repos/totality/Back_End/dataController/dataControllerServerApp.py", line 26, in validateDeviceExists
    Device.get(Device.deviceID == deviceID)
  File "/Users/brendonstanley/virtual/Totality/lib/python3.7/site-packages/peewee.py", line 6091, in get
    return sq.get()
  File "/Users/brendonstanley/virtual/Totality/lib/python3.7/site-packages/peewee.py", line 6501, in get
    (clone.model, sql, params))
Back_End.dataController.models.DeviceDoesNotExist: <Model: Device> instance matching query does not exist:
SQL: SELECT `t1`.`deviceID`, `t1`.`name`, `t1`.`location`, `t1`.`latitude`, `t1`.`longitude`, `t1`.`customerOwner_id`, `t1`.`dataControllerPeriod`, `t1`.`commandControllerPeriod`, `t1`.`timeOfLastCheckIn`, `t1`.`missedCommands`, `t1`.`commandTimeWindow`, `t1`.`status` FROM `device` AS `t1` WHERE (`t1`.`deviceID` IS %s) LIMIT %s OFFSET %s
Params: [None, 1, 0]

2019-07-16 16:17:19,738 - INFO - Data Push Hit: Unable To Verify DID Existence
2019-07-16 16:17:19,738 - INFO - 127.0.0.1 - - [16/Jul/2019 16:17:19] "POST /device/dataPush HTTP/1.1" 400 -
2019-07-16 16:17:19,743 - DEBUG - ('SELECT `t1`.`deviceID`, `t1`.`name`, `t1`.`location`, `t1`.`latitude`, `t1`.`longitude`, `t1`.`customerOwner_id`, `t1`.`dataControllerPeriod`, `t1`.`commandControllerPeriod`, `t1`.`timeOfLastCheckIn`, `t1`.`missedCommands`, `t1`.`commandTimeWindow`, `t1`.`status` FROM `device` AS `t1` WHERE (`t1`.`deviceID` = %s) LIMIT %s OFFSET %s', [1234567890, 1, 0])
2019-07-16 16:17:19,747 - WARNING - Validate DID: DID '1234567890' Failed Validation. Unknown Error.
Exception: <Model: Device> instance matching query does not exist:
SQL: SELECT `t1`.`deviceID`, `t1`.`name`, `t1`.`location`, `t1`.`latitude`, `t1`.`longitude`, `t1`.`customerOwner_id`, `t1`.`dataControllerPeriod`, `t1`.`commandControllerPeriod`, `t1`.`timeOfLastCheckIn`, `t1`.`missedCommands`, `t1`.`commandTimeWindow`, `t1`.`status` FROM `device` AS `t1` WHERE (`t1`.`deviceID` = %s) LIMIT %s OFFSET %s
Params: [1234567890, 1, 0]
TraceBack: Traceback (most recent call last):
  File "/Users/brendonstanley/virtual/Totality/lib/python3.7/site-packages/peewee.py", line 6496, in get
    return clone.execute(database)[0]
  File "/Users/brendonstanley/virtual/Totality/lib/python3.7/site-packages/peewee.py", line 4024, in __getitem__
    return self.row_cache[item]
IndexError: list index out of range

During handling of the above exception, another exception occurred:

Traceback (most recent call last):
  File "/Users/brendonstanley/repos/totality/Back_End/dataController/dataControllerServerApp.py", line 26, in validateDeviceExists
    Device.get(Device.deviceID == deviceID)
  File "/Users/brendonstanley/virtual/Totality/lib/python3.7/site-packages/peewee.py", line 6091, in get
    return sq.get()
  File "/Users/brendonstanley/virtual/Totality/lib/python3.7/site-packages/peewee.py", line 6501, in get
    (clone.model, sql, params))
Back_End.dataController.models.DeviceDoesNotExist: <Model: Device> instance matching query does not exist:
SQL: SELECT `t1`.`deviceID`, `t1`.`name`, `t1`.`location`, `t1`.`latitude`, `t1`.`longitude`, `t1`.`customerOwner_id`, `t1`.`dataControllerPeriod`, `t1`.`commandControllerPeriod`, `t1`.`timeOfLastCheckIn`, `t1`.`missedCommands`, `t1`.`commandTimeWindow`, `t1`.`status` FROM `device` AS `t1` WHERE (`t1`.`deviceID` = %s) LIMIT %s OFFSET %s
Params: [1234567890, 1, 0]

2019-07-16 16:17:19,747 - INFO - Data Push Hit: Unable To Verify DID Existence
2019-07-16 16:17:19,748 - INFO - 127.0.0.1 - - [16/Jul/2019 16:17:19] "POST /device/dataPush HTTP/1.1" 400 -
2019-07-16 16:17:19,752 - INFO - Data Push Hit: No Payload Provided
2019-07-16 16:17:19,752 - DEBUG - ('SELECT `t1`.`deviceID`, `t1`.`name`, `t1`.`location`, `t1`.`latitude`, `t1`.`longitude`, `t1`.`customerOwner_id`, `t1`.`dataControllerPeriod`, `t1`.`commandControllerPeriod`, `t1`.`timeOfLastCheckIn`, `t1`.`missedCommands`, `t1`.`commandTimeWindow`, `t1`.`status` FROM `device` AS `t1` WHERE (`t1`.`deviceID` = %s) LIMIT %s OFFSET %s', [1, 1, 0])
2019-07-16 16:17:19,756 - DEBUG - Validate DID: DID '1' Validate
2019-07-16 16:17:19,757 - DEBUG - ('INSERT INTO `reliabledelivery` (`timeStamp`, `payload`, `sent`, `deviceOwner_id`) VALUES (%s, %s, %s, %s)', [datetime.datetime(2019, 7, 16, 22, 17, 14, 340671), None, False, 1])
2019-07-16 16:17:19,759 - WARNING - Data Push Hit: Unable To Push Data Into RD.
Exception: (1048, "Column 'payload' cannot be null")
TraceBack: Traceback (most recent call last):
  File "/Users/brendonstanley/virtual/Totality/lib/python3.7/site-packages/peewee.py", line 2949, in execute_sql
    cursor.execute(sql, params or ())
  File "/Users/brendonstanley/virtual/Totality/lib/python3.7/site-packages/pymysql/cursors.py", line 170, in execute
    result = self._query(query)
  File "/Users/brendonstanley/virtual/Totality/lib/python3.7/site-packages/pymysql/cursors.py", line 328, in _query
    conn.query(q)
  File "/Users/brendonstanley/virtual/Totality/lib/python3.7/site-packages/pymysql/connections.py", line 517, in query
    self._affected_rows = self._read_query_result(unbuffered=unbuffered)
  File "/Users/brendonstanley/virtual/Totality/lib/python3.7/site-packages/pymysql/connections.py", line 732, in _read_query_result
    result.read()
  File "/Users/brendonstanley/virtual/Totality/lib/python3.7/site-packages/pymysql/connections.py", line 1075, in read
    first_packet = self.connection._read_packet()
  File "/Users/brendonstanley/virtual/Totality/lib/python3.7/site-packages/pymysql/connections.py", line 684, in _read_packet
    packet.check_error()
  File "/Users/brendonstanley/virtual/Totality/lib/python3.7/site-packages/pymysql/protocol.py", line 220, in check_error
    err.raise_mysql_exception(self._data)
  File "/Users/brendonstanley/virtual/Totality/lib/python3.7/site-packages/pymysql/err.py", line 109, in raise_mysql_exception
    raise errorclass(errno, errval)
pymysql.err.IntegrityError: (1048, "Column 'payload' cannot be null")

During handling of the above exception, another exception occurred:

Traceback (most recent call last):
  File "/Users/brendonstanley/repos/totality/Back_End/dataController/dataControllerServerApp.py", line 57, in dataPush
    ReliableDelivery.create(payload=payload, deviceOwner=deviceID)
  File "/Users/brendonstanley/virtual/Totality/lib/python3.7/site-packages/peewee.py", line 6012, in create
    inst.save(force_insert=True)
  File "/Users/brendonstanley/virtual/Totality/lib/python3.7/site-packages/peewee.py", line 6201, in save
    pk = self.insert(**field_dict).execute()
  File "/Users/brendonstanley/virtual/Totality/lib/python3.7/site-packages/peewee.py", line 1785, in inner
    return method(self, database, *args, **kwargs)
  File "/Users/brendonstanley/virtual/Totality/lib/python3.7/site-packages/peewee.py", line 1856, in execute
    return self._execute(database)
  File "/Users/brendonstanley/virtual/Totality/lib/python3.7/site-packages/peewee.py", line 2572, in _execute
    return super(Insert, self)._execute(database)
  File "/Users/brendonstanley/virtual/Totality/lib/python3.7/site-packages/peewee.py", line 2320, in _execute
    cursor = database.execute(self)
  File "/Users/brendonstanley/virtual/Totality/lib/python3.7/site-packages/peewee.py", line 2962, in execute
    return self.execute_sql(sql, params, commit=commit)
  File "/Users/brendonstanley/virtual/Totality/lib/python3.7/site-packages/peewee.py", line 2956, in execute_sql
    self.commit()
  File "/Users/brendonstanley/virtual/Totality/lib/python3.7/site-packages/peewee.py", line 2732, in __exit__
    reraise(new_type, new_type(*exc_args), traceback)
  File "/Users/brendonstanley/virtual/Totality/lib/python3.7/site-packages/peewee.py", line 183, in reraise
    raise value.with_traceback(tb)
  File "/Users/brendonstanley/virtual/Totality/lib/python3.7/site-packages/peewee.py", line 2949, in execute_sql
    cursor.execute(sql, params or ())
  File "/Users/brendonstanley/virtual/Totality/lib/python3.7/site-packages/pymysql/cursors.py", line 170, in execute
    result = self._query(query)
  File "/Users/brendonstanley/virtual/Totality/lib/python3.7/site-packages/pymysql/cursors.py", line 328, in _query
    conn.query(q)
  File "/Users/brendonstanley/virtual/Totality/lib/python3.7/site-packages/pymysql/connections.py", line 517, in query
    self._affected_rows = self._read_query_result(unbuffered=unbuffered)
  File "/Users/brendonstanley/virtual/Totality/lib/python3.7/site-packages/pymysql/connections.py", line 732, in _read_query_result
    result.read()
  File "/Users/brendonstanley/virtual/Totality/lib/python3.7/site-packages/pymysql/connections.py", line 1075, in read
    first_packet = self.connection._read_packet()
  File "/Users/brendonstanley/virtual/Totality/lib/python3.7/site-packages/pymysql/connections.py", line 684, in _read_packet
    packet.check_error()
  File "/Users/brendonstanley/virtual/Totality/lib/python3.7/site-packages/pymysql/protocol.py", line 220, in check_error
    err.raise_mysql_exception(self._data)
  File "/Users/brendonstanley/virtual/Totality/lib/python3.7/site-packages/pymysql/err.py", line 109, in raise_mysql_exception
    raise errorclass(errno, errval)
peewee.IntegrityError: (1048, "Column 'payload' cannot be null")

2019-07-16 16:17:19,759 - INFO - 127.0.0.1 - - [16/Jul/2019 16:17:19] "POST /device/dataPush HTTP/1.1" 400 -
2019-07-16 16:17:19,764 - DEBUG - ('SELECT `t1`.`deviceID`, `t1`.`name`, `t1`.`location`, `t1`.`latitude`, `t1`.`longitude`, `t1`.`customerOwner_id`, `t1`.`dataControllerPeriod`, `t1`.`commandControllerPeriod`, `t1`.`timeOfLastCheckIn`, `t1`.`missedCommands`, `t1`.`commandTimeWindow`, `t1`.`status` FROM `device` AS `t1` WHERE (`t1`.`deviceID` = %s) LIMIT %s OFFSET %s', [1, 1, 0])
2019-07-16 16:17:19,768 - DEBUG - Validate DID: DID '1' Validate
2019-07-16 16:17:19,768 - DEBUG - ('INSERT INTO `reliabledelivery` (`timeStamp`, `payload`, `sent`, `deviceOwner_id`) VALUES (%s, %s, %s, %s)', [datetime.datetime(2019, 7, 16, 22, 17, 14, 340671), "{'TEST': None}", False, 1])
2019-07-16 16:17:19,770 - DEBUG - Data Push Hit: New Entry Into RD
2019-07-16 16:17:19,770 - INFO - 127.0.0.1 - - [16/Jul/2019 16:17:19] "POST /device/dataPush HTTP/1.1" 200 -
