2019-07-19 14:22:07,428 - INFO - 

Launching Program
2019-07-19 14:22:07,434 - DEBUG - Preforming Data-Push
2019-07-19 14:22:07,434 - INFO - All Threads Launched Successfully
2019-07-19 14:22:07,435 - INFO - Starting Tests ...
2019-07-19 14:22:07,442 - INFO - New supervisor Spawned. supervisor Info: {
    "customConfig": "False",
    "deviceID": 1,
    "highEndInt": 100,
    "lowEndInt": 0,
    "samplePeriod": 1,
    "supervisorID": 1,
    "supervisorName": "intMaker",
    "supervisorType": "intMaker"
}

2019-07-19 14:22:07,445 - INFO - New supervisor Spawned. supervisor Info: {
    "customConfig": "True",
    "deviceID": 1,
    "highEndInt": 100,
    "lowEndInt": 0,
    "samplePeriod": 1,
    "supervisorID": 2,
    "supervisorName": "Little Thanos",
    "supervisorType": "intMaker"
}

2019-07-19 14:22:07,445 - INFO - All Launch Supervisors Spawned Successfully
2019-07-19 14:22:07,453 - DEBUG - Starting new HTTP connection (1): localhost:8802
2019-07-19 14:22:07,459 - WARNING - Critical Error Has Occurred While Trying To Connect To Command Server. Error Message: HTTPConnectionPool(host='localhost', port=8802): Max retries exceeded with url: /device/commands/getCommands (Caused by NewConnectionError('<urllib3.connection.HTTPConnection object at 0x106368b70>: Failed to establish a new connection: [Errno 61] Connection refused'))
Traceback (most recent call last):
  File "/Users/brendonstanley/virtual/Totality/lib/python3.7/site-packages/urllib3/connection.py", line 160, in _new_conn
    (self._dns_host, self.port), self.timeout, **extra_kw)
  File "/Users/brendonstanley/virtual/Totality/lib/python3.7/site-packages/urllib3/util/connection.py", line 80, in create_connection
    raise err
  File "/Users/brendonstanley/virtual/Totality/lib/python3.7/site-packages/urllib3/util/connection.py", line 70, in create_connection
    sock.connect(sa)
ConnectionRefusedError: [Errno 61] Connection refused

During handling of the above exception, another exception occurred:

Traceback (most recent call last):
  File "/Users/brendonstanley/virtual/Totality/lib/python3.7/site-packages/urllib3/connectionpool.py", line 603, in urlopen
    chunked=chunked)
  File "/Users/brendonstanley/virtual/Totality/lib/python3.7/site-packages/urllib3/connectionpool.py", line 355, in _make_request
    conn.request(method, url, **httplib_request_kw)
  File "/usr/local/Cellar/python/3.7.3/Frameworks/Python.framework/Versions/3.7/lib/python3.7/http/client.py", line 1229, in request
    self._send_request(method, url, body, headers, encode_chunked)
  File "/usr/local/Cellar/python/3.7.3/Frameworks/Python.framework/Versions/3.7/lib/python3.7/http/client.py", line 1275, in _send_request
    self.endheaders(body, encode_chunked=encode_chunked)
  File "/usr/local/Cellar/python/3.7.3/Frameworks/Python.framework/Versions/3.7/lib/python3.7/http/client.py", line 1224, in endheaders
    self._send_output(message_body, encode_chunked=encode_chunked)
  File "/usr/local/Cellar/python/3.7.3/Frameworks/Python.framework/Versions/3.7/lib/python3.7/http/client.py", line 1016, in _send_output
    self.send(msg)
  File "/usr/local/Cellar/python/3.7.3/Frameworks/Python.framework/Versions/3.7/lib/python3.7/http/client.py", line 956, in send
    self.connect()
  File "/Users/brendonstanley/virtual/Totality/lib/python3.7/site-packages/urllib3/connection.py", line 183, in connect
    conn = self._new_conn()
  File "/Users/brendonstanley/virtual/Totality/lib/python3.7/site-packages/urllib3/connection.py", line 169, in _new_conn
    self, "Failed to establish a new connection: %s" % e)
urllib3.exceptions.NewConnectionError: <urllib3.connection.HTTPConnection object at 0x106368b70>: Failed to establish a new connection: [Errno 61] Connection refused

During handling of the above exception, another exception occurred:

Traceback (most recent call last):
  File "/Users/brendonstanley/virtual/Totality/lib/python3.7/site-packages/requests/adapters.py", line 449, in send
    timeout=timeout
  File "/Users/brendonstanley/virtual/Totality/lib/python3.7/site-packages/urllib3/connectionpool.py", line 641, in urlopen
    _stacktrace=sys.exc_info()[2])
  File "/Users/brendonstanley/virtual/Totality/lib/python3.7/site-packages/urllib3/util/retry.py", line 399, in increment
    raise MaxRetryError(_pool, url, error or ResponseError(cause))
urllib3.exceptions.MaxRetryError: HTTPConnectionPool(host='localhost', port=8802): Max retries exceeded with url: /device/commands/getCommands (Caused by NewConnectionError('<urllib3.connection.HTTPConnection object at 0x106368b70>: Failed to establish a new connection: [Errno 61] Connection refused'))

During handling of the above exception, another exception occurred:

Traceback (most recent call last):
  File "/Users/brendonstanley/repos/totality/Device_Level/Framework/Controllers/commandController.py", line 38, in pullCommands
    commands = requests.post(CommandServerEndPoint, json={"deviceID": self.deviceID})
  File "/Users/brendonstanley/virtual/Totality/lib/python3.7/site-packages/requests/api.py", line 116, in post
    return request('post', url, data=data, json=json, **kwargs)
  File "/Users/brendonstanley/virtual/Totality/lib/python3.7/site-packages/requests/api.py", line 60, in request
    return session.request(method=method, url=url, **kwargs)
  File "/Users/brendonstanley/virtual/Totality/lib/python3.7/site-packages/requests/sessions.py", line 533, in request
    resp = self.send(prep, **send_kwargs)
  File "/Users/brendonstanley/virtual/Totality/lib/python3.7/site-packages/requests/sessions.py", line 646, in send
    r = adapter.send(request, **kwargs)
  File "/Users/brendonstanley/virtual/Totality/lib/python3.7/site-packages/requests/adapters.py", line 516, in send
    raise ConnectionError(e, request=request)
requests.exceptions.ConnectionError: HTTPConnectionPool(host='localhost', port=8802): Max retries exceeded with url: /device/commands/getCommands (Caused by NewConnectionError('<urllib3.connection.HTTPConnection object at 0x106368b70>: Failed to establish a new connection: [Errno 61] Connection refused'))

2019-07-19 14:22:09,438 - INFO - Device_Level Manager Test:
2019-07-19 14:22:10,445 - INFO - New supervisor Spawned. supervisor Info: {
    "customConfig": "False",
    "deviceID": 1,
    "highEndInt": 100,
    "lowEndInt": 0,
    "samplePeriod": 1,
    "supervisorID": 1004,
    "supervisorName": "intMaker",
    "supervisorType": "intMaker"
}

2019-07-19 14:22:10,448 - INFO - New supervisor Spawned. supervisor Info: {
    "customConfig": "True",
    "deviceID": 1,
    "highEndInt": 100,
    "lowEndInt": 0,
    "samplePeriod": 1,
    "supervisorID": 1008,
    "supervisorName": "TestSupervisor",
    "supervisorType": "intMaker"
}

2019-07-19 14:22:10,448 - INFO - supervisor Killed. Dead supervisorID: 1004
2019-07-19 14:22:10,448 - INFO - New supervisor Spawned. supervisor Info: {
    "customConfig": "True",
    "deviceID": 1,
    "highEndInt": 100,
    "lowEndInt": 0,
    "samplePeriod": 1,
    "supervisorID": 1004,
    "supervisorName": "UpdatedSupervisor",
    "supervisorType": "intMaker"
}

2019-07-19 14:22:10,448 - DEBUG - Starting CleanUp
2019-07-19 14:22:10,448 - DEBUG - Cleaning Supervisor ID: 1008
2019-07-19 14:22:10,448 - INFO - supervisor Killed. Dead supervisorID: 1008
2019-07-19 14:22:12,437 - DEBUG - Preforming Data-Push
2019-07-19 14:22:12,441 - DEBUG - Starting new HTTP connection (1): localhost:8801
2019-07-19 14:22:12,442 - WARNING - Unable To Push Package To DB.
Exception: HTTPConnectionPool(host='localhost', port=8801): Max retries exceeded with url: /device/dataPush (Caused by NewConnectionError('<urllib3.connection.HTTPConnection object at 0x10707b0f0>: Failed to establish a new connection: [Errno 61] Connection refused'))
TraceBack: <module 'traceback' from '/usr/local/Cellar/python/3.7.3/Frameworks/Python.framework/Versions/3.7/lib/python3.7/traceback.py'>
2019-07-19 14:22:12,443 - DEBUG - Starting new HTTP connection (1): localhost:8801
2019-07-19 14:22:12,444 - WARNING - Unable To Push Package To DB.
Exception: HTTPConnectionPool(host='localhost', port=8801): Max retries exceeded with url: /device/dataPush (Caused by NewConnectionError('<urllib3.connection.HTTPConnection object at 0x10634b828>: Failed to establish a new connection: [Errno 61] Connection refused'))
TraceBack: <module 'traceback' from '/usr/local/Cellar/python/3.7.3/Frameworks/Python.framework/Versions/3.7/lib/python3.7/traceback.py'>
2019-07-19 14:22:12,446 - DEBUG - Starting new HTTP connection (1): localhost:8801
2019-07-19 14:22:12,447 - WARNING - Unable To Push Package To DB.
Exception: HTTPConnectionPool(host='localhost', port=8801): Max retries exceeded with url: /device/dataPush (Caused by NewConnectionError('<urllib3.connection.HTTPConnection object at 0x10707b588>: Failed to establish a new connection: [Errno 61] Connection refused'))
TraceBack: <module 'traceback' from '/usr/local/Cellar/python/3.7.3/Frameworks/Python.framework/Versions/3.7/lib/python3.7/traceback.py'>
2019-07-19 14:22:12,448 - DEBUG - Starting new HTTP connection (1): localhost:8801
2019-07-19 14:22:12,449 - WARNING - Unable To Push Package To DB.
Exception: HTTPConnectionPool(host='localhost', port=8801): Max retries exceeded with url: /device/dataPush (Caused by NewConnectionError('<urllib3.connection.HTTPConnection object at 0x10707bc50>: Failed to establish a new connection: [Errno 61] Connection refused'))
TraceBack: <module 'traceback' from '/usr/local/Cellar/python/3.7.3/Frameworks/Python.framework/Versions/3.7/lib/python3.7/traceback.py'>
2019-07-19 14:22:12,451 - DEBUG - Starting new HTTP connection (1): localhost:8801
2019-07-19 14:22:12,452 - WARNING - Unable To Push Package To DB.
Exception: HTTPConnectionPool(host='localhost', port=8801): Max retries exceeded with url: /device/dataPush (Caused by NewConnectionError('<urllib3.connection.HTTPConnection object at 0x10708d358>: Failed to establish a new connection: [Errno 61] Connection refused'))
TraceBack: <module 'traceback' from '/usr/local/Cellar/python/3.7.3/Frameworks/Python.framework/Versions/3.7/lib/python3.7/traceback.py'>
2019-07-19 14:22:12,452 - DEBUG - Cleaning Supervisor ID: 1004
2019-07-19 14:22:12,452 - INFO - supervisor Killed. Dead supervisorID: 1004
2019-07-19 14:22:12,454 - DEBUG - Starting new HTTP connection (1): localhost:8801
2019-07-19 14:22:12,455 - WARNING - Unable To Push Package To DB.
Exception: HTTPConnectionPool(host='localhost', port=8801): Max retries exceeded with url: /device/dataPush (Caused by NewConnectionError('<urllib3.connection.HTTPConnection object at 0x10708d898>: Failed to establish a new connection: [Errno 61] Connection refused'))
TraceBack: <module 'traceback' from '/usr/local/Cellar/python/3.7.3/Frameworks/Python.framework/Versions/3.7/lib/python3.7/traceback.py'>
2019-07-19 14:22:12,456 - DEBUG - Starting new HTTP connection (1): localhost:8801
2019-07-19 14:22:12,457 - WARNING - Unable To Push Package To DB.
Exception: HTTPConnectionPool(host='localhost', port=8801): Max retries exceeded with url: /device/dataPush (Caused by NewConnectionError('<urllib3.connection.HTTPConnection object at 0x10709d080>: Failed to establish a new connection: [Errno 61] Connection refused'))
TraceBack: <module 'traceback' from '/usr/local/Cellar/python/3.7.3/Frameworks/Python.framework/Versions/3.7/lib/python3.7/traceback.py'>
2019-07-19 14:22:12,458 - DEBUG - Starting new HTTP connection (1): localhost:8801
2019-07-19 14:22:12,459 - WARNING - Unable To Push Package To DB.
Exception: HTTPConnectionPool(host='localhost', port=8801): Max retries exceeded with url: /device/dataPush (Caused by NewConnectionError('<urllib3.connection.HTTPConnection object at 0x10708dac8>: Failed to establish a new connection: [Errno 61] Connection refused'))
TraceBack: <module 'traceback' from '/usr/local/Cellar/python/3.7.3/Frameworks/Python.framework/Versions/3.7/lib/python3.7/traceback.py'>
2019-07-19 14:22:12,460 - DEBUG - Starting new HTTP connection (1): localhost:8801
2019-07-19 14:22:12,461 - WARNING - Unable To Push Package To DB.
Exception: HTTPConnectionPool(host='localhost', port=8801): Max retries exceeded with url: /device/dataPush (Caused by NewConnectionError('<urllib3.connection.HTTPConnection object at 0x10708d128>: Failed to establish a new connection: [Errno 61] Connection refused'))
TraceBack: <module 'traceback' from '/usr/local/Cellar/python/3.7.3/Frameworks/Python.framework/Versions/3.7/lib/python3.7/traceback.py'>
2019-07-19 14:22:12,461 - WARNING - File Not Error Occurred When Trying To Save Data Locally.
Error Message: [Errno 2] No such file or directory: 'Local_Data/SupervisorId_1008/localCSV.csv'
Traceback (most recent call last):
  File "/Users/brendonstanley/repos/totality/Device_Level/Framework/Controllers/dataController.py", line 52, in localCSV
    with open(path, 'a') as csvFile:
FileNotFoundError: [Errno 2] No such file or directory: 'Local_Data/SupervisorId_1008/localCSV.csv'

2019-07-19 14:22:12,462 - DEBUG - Starting new HTTP connection (1): localhost:8801
2019-07-19 14:22:12,463 - WARNING - Unable To Push Package To DB.
Exception: HTTPConnectionPool(host='localhost', port=8801): Max retries exceeded with url: /device/dataPush (Caused by NewConnectionError('<urllib3.connection.HTTPConnection object at 0x106368ba8>: Failed to establish a new connection: [Errno 61] Connection refused'))
TraceBack: <module 'traceback' from '/usr/local/Cellar/python/3.7.3/Frameworks/Python.framework/Versions/3.7/lib/python3.7/traceback.py'>
2019-07-19 14:22:12,464 - DEBUG - Starting new HTTP connection (1): localhost:8802
2019-07-19 14:22:12,465 - DEBUG - Starting new HTTP connection (1): localhost:8801
2019-07-19 14:22:12,466 - WARNING - Critical Error Has Occurred While Trying To Connect To Command Server. Error Message: HTTPConnectionPool(host='localhost', port=8802): Max retries exceeded with url: /device/commands/getCommands (Caused by NewConnectionError('<urllib3.connection.HTTPConnection object at 0x106390710>: Failed to establish a new connection: [Errno 61] Connection refused'))
Traceback (most recent call last):
  File "/Users/brendonstanley/virtual/Totality/lib/python3.7/site-packages/urllib3/connection.py", line 160, in _new_conn
    (self._dns_host, self.port), self.timeout, **extra_kw)
  File "/Users/brendonstanley/virtual/Totality/lib/python3.7/site-packages/urllib3/util/connection.py", line 80, in create_connection
    raise err
  File "/Users/brendonstanley/virtual/Totality/lib/python3.7/site-packages/urllib3/util/connection.py", line 70, in create_connection
    sock.connect(sa)
ConnectionRefusedError: [Errno 61] Connection refused

During handling of the above exception, another exception occurred:

Traceback (most recent call last):
  File "/Users/brendonstanley/virtual/Totality/lib/python3.7/site-packages/urllib3/connectionpool.py", line 603, in urlopen
    chunked=chunked)
  File "/Users/brendonstanley/virtual/Totality/lib/python3.7/site-packages/urllib3/connectionpool.py", line 355, in _make_request
    conn.request(method, url, **httplib_request_kw)
  File "/usr/local/Cellar/python/3.7.3/Frameworks/Python.framework/Versions/3.7/lib/python3.7/http/client.py", line 1229, in request
    self._send_request(method, url, body, headers, encode_chunked)
  File "/usr/local/Cellar/python/3.7.3/Frameworks/Python.framework/Versions/3.7/lib/python3.7/http/client.py", line 1275, in _send_request
    self.endheaders(body, encode_chunked=encode_chunked)
  File "/usr/local/Cellar/python/3.7.3/Frameworks/Python.framework/Versions/3.7/lib/python3.7/http/client.py", line 1224, in endheaders
    self._send_output(message_body, encode_chunked=encode_chunked)
  File "/usr/local/Cellar/python/3.7.3/Frameworks/Python.framework/Versions/3.7/lib/python3.7/http/client.py", line 1016, in _send_output
    self.send(msg)
  File "/usr/local/Cellar/python/3.7.3/Frameworks/Python.framework/Versions/3.7/lib/python3.7/http/client.py", line 956, in send
    self.connect()
  File "/Users/brendonstanley/virtual/Totality/lib/python3.7/site-packages/urllib3/connection.py", line 183, in connect
    conn = self._new_conn()
  File "/Users/brendonstanley/virtual/Totality/lib/python3.7/site-packages/urllib3/connection.py", line 169, in _new_conn
    self, "Failed to establish a new connection: %s" % e)
urllib3.exceptions.NewConnectionError: <urllib3.connection.HTTPConnection object at 0x106390710>: Failed to establish a new connection: [Errno 61] Connection refused

During handling of the above exception, another exception occurred:

Traceback (most recent call last):
  File "/Users/brendonstanley/virtual/Totality/lib/python3.7/site-packages/requests/adapters.py", line 449, in send
    timeout=timeout
  File "/Users/brendonstanley/virtual/Totality/lib/python3.7/site-packages/urllib3/connectionpool.py", line 641, in urlopen
    _stacktrace=sys.exc_info()[2])
  File "/Users/brendonstanley/virtual/Totality/lib/python3.7/site-packages/urllib3/util/retry.py", line 399, in increment
    raise MaxRetryError(_pool, url, error or ResponseError(cause))
urllib3.exceptions.MaxRetryError: HTTPConnectionPool(host='localhost', port=8802): Max retries exceeded with url: /device/commands/getCommands (Caused by NewConnectionError('<urllib3.connection.HTTPConnection object at 0x106390710>: Failed to establish a new connection: [Errno 61] Connection refused'))

During handling of the above exception, another exception occurred:

Traceback (most recent call last):
  File "/Users/brendonstanley/repos/totality/Device_Level/Framework/Controllers/commandController.py", line 38, in pullCommands
    commands = requests.post(CommandServerEndPoint, json={"deviceID": self.deviceID})
  File "/Users/brendonstanley/virtual/Totality/lib/python3.7/site-packages/requests/api.py", line 116, in post
    return request('post', url, data=data, json=json, **kwargs)
  File "/Users/brendonstanley/virtual/Totality/lib/python3.7/site-packages/requests/api.py", line 60, in request
    return session.request(method=method, url=url, **kwargs)
  File "/Users/brendonstanley/virtual/Totality/lib/python3.7/site-packages/requests/sessions.py", line 533, in request
    resp = self.send(prep, **send_kwargs)
  File "/Users/brendonstanley/virtual/Totality/lib/python3.7/site-packages/requests/sessions.py", line 646, in send
    r = adapter.send(request, **kwargs)
  File "/Users/brendonstanley/virtual/Totality/lib/python3.7/site-packages/requests/adapters.py", line 516, in send
    raise ConnectionError(e, request=request)
requests.exceptions.ConnectionError: HTTPConnectionPool(host='localhost', port=8802): Max retries exceeded with url: /device/commands/getCommands (Caused by NewConnectionError('<urllib3.connection.HTTPConnection object at 0x106390710>: Failed to establish a new connection: [Errno 61] Connection refused'))

2019-07-19 14:22:12,466 - WARNING - Unable To Push Package To DB.
Exception: HTTPConnectionPool(host='localhost', port=8801): Max retries exceeded with url: /device/dataPush (Caused by NewConnectionError('<urllib3.connection.HTTPConnection object at 0x106390cc0>: Failed to establish a new connection: [Errno 61] Connection refused'))
TraceBack: <module 'traceback' from '/usr/local/Cellar/python/3.7.3/Frameworks/Python.framework/Versions/3.7/lib/python3.7/traceback.py'>
2019-07-19 14:22:12,467 - DEBUG - Starting new HTTP connection (1): localhost:8801
2019-07-19 14:22:12,468 - WARNING - Unable To Push Package To DB.
Exception: HTTPConnectionPool(host='localhost', port=8801): Max retries exceeded with url: /device/dataPush (Caused by NewConnectionError('<urllib3.connection.HTTPConnection object at 0x10709d7b8>: Failed to establish a new connection: [Errno 61] Connection refused'))
TraceBack: <module 'traceback' from '/usr/local/Cellar/python/3.7.3/Frameworks/Python.framework/Versions/3.7/lib/python3.7/traceback.py'>
2019-07-19 14:22:12,469 - DEBUG - Starting new HTTP connection (1): localhost:8801
2019-07-19 14:22:12,470 - WARNING - Unable To Push Package To DB.
Exception: HTTPConnectionPool(host='localhost', port=8801): Max retries exceeded with url: /device/dataPush (Caused by NewConnectionError('<urllib3.connection.HTTPConnection object at 0x10709de80>: Failed to establish a new connection: [Errno 61] Connection refused'))
TraceBack: <module 'traceback' from '/usr/local/Cellar/python/3.7.3/Frameworks/Python.framework/Versions/3.7/lib/python3.7/traceback.py'>
2019-07-19 14:22:12,471 - DEBUG - Starting new HTTP connection (1): localhost:8801
2019-07-19 14:22:12,472 - WARNING - Unable To Push Package To DB.
Exception: HTTPConnectionPool(host='localhost', port=8801): Max retries exceeded with url: /device/dataPush (Caused by NewConnectionError('<urllib3.connection.HTTPConnection object at 0x10634bb38>: Failed to establish a new connection: [Errno 61] Connection refused'))
TraceBack: <module 'traceback' from '/usr/local/Cellar/python/3.7.3/Frameworks/Python.framework/Versions/3.7/lib/python3.7/traceback.py'>
2019-07-19 14:22:12,473 - DEBUG - Starting new HTTP connection (1): localhost:8801
2019-07-19 14:22:12,474 - WARNING - Unable To Push Package To DB.
Exception: HTTPConnectionPool(host='localhost', port=8801): Max retries exceeded with url: /device/dataPush (Caused by NewConnectionError('<urllib3.connection.HTTPConnection object at 0x106390fd0>: Failed to establish a new connection: [Errno 61] Connection refused'))
TraceBack: <module 'traceback' from '/usr/local/Cellar/python/3.7.3/Frameworks/Python.framework/Versions/3.7/lib/python3.7/traceback.py'>
2019-07-19 14:22:14,456 - DEBUG - deviceMangerTester: CleanUp Complete

2019-07-19 14:22:14,457 - DEBUG - deviceManagerTester: All Tests Passed Successfully

2019-07-19 14:22:17,470 - DEBUG - Starting new HTTP connection (1): localhost:8802
2019-07-19 14:22:17,472 - WARNING - Critical Error Has Occurred While Trying To Connect To Command Server. Error Message: HTTPConnectionPool(host='localhost', port=8802): Max retries exceeded with url: /device/commands/getCommands (Caused by NewConnectionError('<urllib3.connection.HTTPConnection object at 0x106390e48>: Failed to establish a new connection: [Errno 61] Connection refused'))
Traceback (most recent call last):
  File "/Users/brendonstanley/virtual/Totality/lib/python3.7/site-packages/urllib3/connection.py", line 160, in _new_conn
    (self._dns_host, self.port), self.timeout, **extra_kw)
  File "/Users/brendonstanley/virtual/Totality/lib/python3.7/site-packages/urllib3/util/connection.py", line 80, in create_connection
    raise err
  File "/Users/brendonstanley/virtual/Totality/lib/python3.7/site-packages/urllib3/util/connection.py", line 70, in create_connection
    sock.connect(sa)
ConnectionRefusedError: [Errno 61] Connection refused

During handling of the above exception, another exception occurred:

Traceback (most recent call last):
  File "/Users/brendonstanley/virtual/Totality/lib/python3.7/site-packages/urllib3/connectionpool.py", line 603, in urlopen
    chunked=chunked)
  File "/Users/brendonstanley/virtual/Totality/lib/python3.7/site-packages/urllib3/connectionpool.py", line 355, in _make_request
    conn.request(method, url, **httplib_request_kw)
  File "/usr/local/Cellar/python/3.7.3/Frameworks/Python.framework/Versions/3.7/lib/python3.7/http/client.py", line 1229, in request
    self._send_request(method, url, body, headers, encode_chunked)
  File "/usr/local/Cellar/python/3.7.3/Frameworks/Python.framework/Versions/3.7/lib/python3.7/http/client.py", line 1275, in _send_request
    self.endheaders(body, encode_chunked=encode_chunked)
  File "/usr/local/Cellar/python/3.7.3/Frameworks/Python.framework/Versions/3.7/lib/python3.7/http/client.py", line 1224, in endheaders
    self._send_output(message_body, encode_chunked=encode_chunked)
  File "/usr/local/Cellar/python/3.7.3/Frameworks/Python.framework/Versions/3.7/lib/python3.7/http/client.py", line 1016, in _send_output
    self.send(msg)
  File "/usr/local/Cellar/python/3.7.3/Frameworks/Python.framework/Versions/3.7/lib/python3.7/http/client.py", line 956, in send
    self.connect()
  File "/Users/brendonstanley/virtual/Totality/lib/python3.7/site-packages/urllib3/connection.py", line 183, in connect
    conn = self._new_conn()
  File "/Users/brendonstanley/virtual/Totality/lib/python3.7/site-packages/urllib3/connection.py", line 169, in _new_conn
    self, "Failed to establish a new connection: %s" % e)
urllib3.exceptions.NewConnectionError: <urllib3.connection.HTTPConnection object at 0x106390e48>: Failed to establish a new connection: [Errno 61] Connection refused

During handling of the above exception, another exception occurred:

Traceback (most recent call last):
  File "/Users/brendonstanley/virtual/Totality/lib/python3.7/site-packages/requests/adapters.py", line 449, in send
    timeout=timeout
  File "/Users/brendonstanley/virtual/Totality/lib/python3.7/site-packages/urllib3/connectionpool.py", line 641, in urlopen
    _stacktrace=sys.exc_info()[2])
  File "/Users/brendonstanley/virtual/Totality/lib/python3.7/site-packages/urllib3/util/retry.py", line 399, in increment
    raise MaxRetryError(_pool, url, error or ResponseError(cause))
urllib3.exceptions.MaxRetryError: HTTPConnectionPool(host='localhost', port=8802): Max retries exceeded with url: /device/commands/getCommands (Caused by NewConnectionError('<urllib3.connection.HTTPConnection object at 0x106390e48>: Failed to establish a new connection: [Errno 61] Connection refused'))

During handling of the above exception, another exception occurred:

Traceback (most recent call last):
  File "/Users/brendonstanley/repos/totality/Device_Level/Framework/Controllers/commandController.py", line 38, in pullCommands
    commands = requests.post(CommandServerEndPoint, json={"deviceID": self.deviceID})
  File "/Users/brendonstanley/virtual/Totality/lib/python3.7/site-packages/requests/api.py", line 116, in post
    return request('post', url, data=data, json=json, **kwargs)
  File "/Users/brendonstanley/virtual/Totality/lib/python3.7/site-packages/requests/api.py", line 60, in request
    return session.request(method=method, url=url, **kwargs)
  File "/Users/brendonstanley/virtual/Totality/lib/python3.7/site-packages/requests/sessions.py", line 533, in request
    resp = self.send(prep, **send_kwargs)
  File "/Users/brendonstanley/virtual/Totality/lib/python3.7/site-packages/requests/sessions.py", line 646, in send
    r = adapter.send(request, **kwargs)
  File "/Users/brendonstanley/virtual/Totality/lib/python3.7/site-packages/requests/adapters.py", line 516, in send
    raise ConnectionError(e, request=request)
requests.exceptions.ConnectionError: HTTPConnectionPool(host='localhost', port=8802): Max retries exceeded with url: /device/commands/getCommands (Caused by NewConnectionError('<urllib3.connection.HTTPConnection object at 0x106390e48>: Failed to establish a new connection: [Errno 61] Connection refused'))

2019-07-19 14:22:17,478 - DEBUG - Preforming Data-Push
2019-07-19 14:22:17,481 - DEBUG - Starting new HTTP connection (1): localhost:8801
2019-07-19 14:22:17,482 - WARNING - Unable To Push Package To DB.
Exception: HTTPConnectionPool(host='localhost', port=8801): Max retries exceeded with url: /device/dataPush (Caused by NewConnectionError('<urllib3.connection.HTTPConnection object at 0x10709de48>: Failed to establish a new connection: [Errno 61] Connection refused'))
TraceBack: <module 'traceback' from '/usr/local/Cellar/python/3.7.3/Frameworks/Python.framework/Versions/3.7/lib/python3.7/traceback.py'>
2019-07-19 14:22:17,484 - DEBUG - Starting new HTTP connection (1): localhost:8801
2019-07-19 14:22:17,484 - WARNING - Unable To Push Package To DB.
Exception: HTTPConnectionPool(host='localhost', port=8801): Max retries exceeded with url: /device/dataPush (Caused by NewConnectionError('<urllib3.connection.HTTPConnection object at 0x10709d390>: Failed to establish a new connection: [Errno 61] Connection refused'))
TraceBack: <module 'traceback' from '/usr/local/Cellar/python/3.7.3/Frameworks/Python.framework/Versions/3.7/lib/python3.7/traceback.py'>
2019-07-19 14:22:17,486 - DEBUG - Starting new HTTP connection (1): localhost:8801
2019-07-19 14:22:17,487 - WARNING - Unable To Push Package To DB.
Exception: HTTPConnectionPool(host='localhost', port=8801): Max retries exceeded with url: /device/dataPush (Caused by NewConnectionError('<urllib3.connection.HTTPConnection object at 0x10708d208>: Failed to establish a new connection: [Errno 61] Connection refused'))
TraceBack: <module 'traceback' from '/usr/local/Cellar/python/3.7.3/Frameworks/Python.framework/Versions/3.7/lib/python3.7/traceback.py'>
2019-07-19 14:22:17,489 - DEBUG - Starting new HTTP connection (1): localhost:8801
2019-07-19 14:22:17,489 - WARNING - Unable To Push Package To DB.
Exception: HTTPConnectionPool(host='localhost', port=8801): Max retries exceeded with url: /device/dataPush (Caused by NewConnectionError('<urllib3.connection.HTTPConnection object at 0x10708d828>: Failed to establish a new connection: [Errno 61] Connection refused'))
TraceBack: <module 'traceback' from '/usr/local/Cellar/python/3.7.3/Frameworks/Python.framework/Versions/3.7/lib/python3.7/traceback.py'>
2019-07-19 14:22:17,491 - DEBUG - Starting new HTTP connection (1): localhost:8801
2019-07-19 14:22:17,492 - WARNING - Unable To Push Package To DB.
Exception: HTTPConnectionPool(host='localhost', port=8801): Max retries exceeded with url: /device/dataPush (Caused by NewConnectionError('<urllib3.connection.HTTPConnection object at 0x106390c50>: Failed to establish a new connection: [Errno 61] Connection refused'))
TraceBack: <module 'traceback' from '/usr/local/Cellar/python/3.7.3/Frameworks/Python.framework/Versions/3.7/lib/python3.7/traceback.py'>
2019-07-19 14:22:17,493 - DEBUG - Starting new HTTP connection (1): localhost:8801
2019-07-19 14:22:17,494 - WARNING - Unable To Push Package To DB.
Exception: HTTPConnectionPool(host='localhost', port=8801): Max retries exceeded with url: /device/dataPush (Caused by NewConnectionError('<urllib3.connection.HTTPConnection object at 0x106390da0>: Failed to establish a new connection: [Errno 61] Connection refused'))
TraceBack: <module 'traceback' from '/usr/local/Cellar/python/3.7.3/Frameworks/Python.framework/Versions/3.7/lib/python3.7/traceback.py'>
2019-07-19 14:22:17,496 - DEBUG - Starting new HTTP connection (1): localhost:8801
2019-07-19 14:22:17,496 - WARNING - Unable To Push Package To DB.
Exception: HTTPConnectionPool(host='localhost', port=8801): Max retries exceeded with url: /device/dataPush (Caused by NewConnectionError('<urllib3.connection.HTTPConnection object at 0x10634b710>: Failed to establish a new connection: [Errno 61] Connection refused'))
TraceBack: <module 'traceback' from '/usr/local/Cellar/python/3.7.3/Frameworks/Python.framework/Versions/3.7/lib/python3.7/traceback.py'>
2019-07-19 14:22:17,498 - DEBUG - Starting new HTTP connection (1): localhost:8801
2019-07-19 14:22:17,498 - WARNING - Unable To Push Package To DB.
Exception: HTTPConnectionPool(host='localhost', port=8801): Max retries exceeded with url: /device/dataPush (Caused by NewConnectionError('<urllib3.connection.HTTPConnection object at 0x10708d470>: Failed to establish a new connection: [Errno 61] Connection refused'))
TraceBack: <module 'traceback' from '/usr/local/Cellar/python/3.7.3/Frameworks/Python.framework/Versions/3.7/lib/python3.7/traceback.py'>
2019-07-19 14:22:17,500 - DEBUG - Starting new HTTP connection (1): localhost:8801
2019-07-19 14:22:17,500 - WARNING - Unable To Push Package To DB.
Exception: HTTPConnectionPool(host='localhost', port=8801): Max retries exceeded with url: /device/dataPush (Caused by NewConnectionError('<urllib3.connection.HTTPConnection object at 0x10708d6a0>: Failed to establish a new connection: [Errno 61] Connection refused'))
TraceBack: <module 'traceback' from '/usr/local/Cellar/python/3.7.3/Frameworks/Python.framework/Versions/3.7/lib/python3.7/traceback.py'>
2019-07-19 14:22:17,502 - DEBUG - Starting new HTTP connection (1): localhost:8801
2019-07-19 14:22:17,502 - WARNING - Unable To Push Package To DB.
Exception: HTTPConnectionPool(host='localhost', port=8801): Max retries exceeded with url: /device/dataPush (Caused by NewConnectionError('<urllib3.connection.HTTPConnection object at 0x107072518>: Failed to establish a new connection: [Errno 61] Connection refused'))
TraceBack: <module 'traceback' from '/usr/local/Cellar/python/3.7.3/Frameworks/Python.framework/Versions/3.7/lib/python3.7/traceback.py'>
2019-07-19 14:22:22,477 - DEBUG - Starting new HTTP connection (1): localhost:8802
2019-07-19 14:22:22,478 - WARNING - Critical Error Has Occurred While Trying To Connect To Command Server. Error Message: HTTPConnectionPool(host='localhost', port=8802): Max retries exceeded with url: /device/commands/getCommands (Caused by NewConnectionError('<urllib3.connection.HTTPConnection object at 0x107072da0>: Failed to establish a new connection: [Errno 61] Connection refused'))
Traceback (most recent call last):
  File "/Users/brendonstanley/virtual/Totality/lib/python3.7/site-packages/urllib3/connection.py", line 160, in _new_conn
    (self._dns_host, self.port), self.timeout, **extra_kw)
  File "/Users/brendonstanley/virtual/Totality/lib/python3.7/site-packages/urllib3/util/connection.py", line 80, in create_connection
    raise err
  File "/Users/brendonstanley/virtual/Totality/lib/python3.7/site-packages/urllib3/util/connection.py", line 70, in create_connection
    sock.connect(sa)
ConnectionRefusedError: [Errno 61] Connection refused

During handling of the above exception, another exception occurred:

Traceback (most recent call last):
  File "/Users/brendonstanley/virtual/Totality/lib/python3.7/site-packages/urllib3/connectionpool.py", line 603, in urlopen
    chunked=chunked)
  File "/Users/brendonstanley/virtual/Totality/lib/python3.7/site-packages/urllib3/connectionpool.py", line 355, in _make_request
    conn.request(method, url, **httplib_request_kw)
  File "/usr/local/Cellar/python/3.7.3/Frameworks/Python.framework/Versions/3.7/lib/python3.7/http/client.py", line 1229, in request
    self._send_request(method, url, body, headers, encode_chunked)
  File "/usr/local/Cellar/python/3.7.3/Frameworks/Python.framework/Versions/3.7/lib/python3.7/http/client.py", line 1275, in _send_request
    self.endheaders(body, encode_chunked=encode_chunked)
  File "/usr/local/Cellar/python/3.7.3/Frameworks/Python.framework/Versions/3.7/lib/python3.7/http/client.py", line 1224, in endheaders
    self._send_output(message_body, encode_chunked=encode_chunked)
  File "/usr/local/Cellar/python/3.7.3/Frameworks/Python.framework/Versions/3.7/lib/python3.7/http/client.py", line 1016, in _send_output
    self.send(msg)
  File "/usr/local/Cellar/python/3.7.3/Frameworks/Python.framework/Versions/3.7/lib/python3.7/http/client.py", line 956, in send
    self.connect()
  File "/Users/brendonstanley/virtual/Totality/lib/python3.7/site-packages/urllib3/connection.py", line 183, in connect
    conn = self._new_conn()
  File "/Users/brendonstanley/virtual/Totality/lib/python3.7/site-packages/urllib3/connection.py", line 169, in _new_conn
    self, "Failed to establish a new connection: %s" % e)
urllib3.exceptions.NewConnectionError: <urllib3.connection.HTTPConnection object at 0x107072da0>: Failed to establish a new connection: [Errno 61] Connection refused

During handling of the above exception, another exception occurred:

Traceback (most recent call last):
  File "/Users/brendonstanley/virtual/Totality/lib/python3.7/site-packages/requests/adapters.py", line 449, in send
    timeout=timeout
  File "/Users/brendonstanley/virtual/Totality/lib/python3.7/site-packages/urllib3/connectionpool.py", line 641, in urlopen
    _stacktrace=sys.exc_info()[2])
  File "/Users/brendonstanley/virtual/Totality/lib/python3.7/site-packages/urllib3/util/retry.py", line 399, in increment
    raise MaxRetryError(_pool, url, error or ResponseError(cause))
urllib3.exceptions.MaxRetryError: HTTPConnectionPool(host='localhost', port=8802): Max retries exceeded with url: /device/commands/getCommands (Caused by NewConnectionError('<urllib3.connection.HTTPConnection object at 0x107072da0>: Failed to establish a new connection: [Errno 61] Connection refused'))

During handling of the above exception, another exception occurred:

Traceback (most recent call last):
  File "/Users/brendonstanley/repos/totality/Device_Level/Framework/Controllers/commandController.py", line 38, in pullCommands
    commands = requests.post(CommandServerEndPoint, json={"deviceID": self.deviceID})
  File "/Users/brendonstanley/virtual/Totality/lib/python3.7/site-packages/requests/api.py", line 116, in post
    return request('post', url, data=data, json=json, **kwargs)
  File "/Users/brendonstanley/virtual/Totality/lib/python3.7/site-packages/requests/api.py", line 60, in request
    return session.request(method=method, url=url, **kwargs)
  File "/Users/brendonstanley/virtual/Totality/lib/python3.7/site-packages/requests/sessions.py", line 533, in request
    resp = self.send(prep, **send_kwargs)
  File "/Users/brendonstanley/virtual/Totality/lib/python3.7/site-packages/requests/sessions.py", line 646, in send
    r = adapter.send(request, **kwargs)
  File "/Users/brendonstanley/virtual/Totality/lib/python3.7/site-packages/requests/adapters.py", line 516, in send
    raise ConnectionError(e, request=request)
requests.exceptions.ConnectionError: HTTPConnectionPool(host='localhost', port=8802): Max retries exceeded with url: /device/commands/getCommands (Caused by NewConnectionError('<urllib3.connection.HTTPConnection object at 0x107072da0>: Failed to establish a new connection: [Errno 61] Connection refused'))

2019-07-19 14:22:22,502 - DEBUG - Preforming Data-Push
2019-07-19 14:22:22,505 - DEBUG - Starting new HTTP connection (1): localhost:8801
2019-07-19 14:22:22,506 - WARNING - Unable To Push Package To DB.
Exception: HTTPConnectionPool(host='localhost', port=8801): Max retries exceeded with url: /device/dataPush (Caused by NewConnectionError('<urllib3.connection.HTTPConnection object at 0x1070729e8>: Failed to establish a new connection: [Errno 61] Connection refused'))
TraceBack: <module 'traceback' from '/usr/local/Cellar/python/3.7.3/Frameworks/Python.framework/Versions/3.7/lib/python3.7/traceback.py'>
2019-07-19 14:22:22,508 - DEBUG - Starting new HTTP connection (1): localhost:8801
2019-07-19 14:22:22,509 - WARNING - Unable To Push Package To DB.
Exception: HTTPConnectionPool(host='localhost', port=8801): Max retries exceeded with url: /device/dataPush (Caused by NewConnectionError('<urllib3.connection.HTTPConnection object at 0x107072358>: Failed to establish a new connection: [Errno 61] Connection refused'))
TraceBack: <module 'traceback' from '/usr/local/Cellar/python/3.7.3/Frameworks/Python.framework/Versions/3.7/lib/python3.7/traceback.py'>
2019-07-19 14:22:22,511 - DEBUG - Starting new HTTP connection (1): localhost:8801
2019-07-19 14:22:22,511 - WARNING - Unable To Push Package To DB.
Exception: HTTPConnectionPool(host='localhost', port=8801): Max retries exceeded with url: /device/dataPush (Caused by NewConnectionError('<urllib3.connection.HTTPConnection object at 0x106368b00>: Failed to establish a new connection: [Errno 61] Connection refused'))
TraceBack: <module 'traceback' from '/usr/local/Cellar/python/3.7.3/Frameworks/Python.framework/Versions/3.7/lib/python3.7/traceback.py'>
2019-07-19 14:22:22,513 - DEBUG - Starting new HTTP connection (1): localhost:8801
2019-07-19 14:22:22,514 - WARNING - Unable To Push Package To DB.
Exception: HTTPConnectionPool(host='localhost', port=8801): Max retries exceeded with url: /device/dataPush (Caused by NewConnectionError('<urllib3.connection.HTTPConnection object at 0x106390dd8>: Failed to establish a new connection: [Errno 61] Connection refused'))
TraceBack: <module 'traceback' from '/usr/local/Cellar/python/3.7.3/Frameworks/Python.framework/Versions/3.7/lib/python3.7/traceback.py'>
2019-07-19 14:22:22,515 - DEBUG - Starting new HTTP connection (1): localhost:8801
2019-07-19 14:22:22,516 - WARNING - Unable To Push Package To DB.
Exception: HTTPConnectionPool(host='localhost', port=8801): Max retries exceeded with url: /device/dataPush (Caused by NewConnectionError('<urllib3.connection.HTTPConnection object at 0x1063907f0>: Failed to establish a new connection: [Errno 61] Connection refused'))
TraceBack: <module 'traceback' from '/usr/local/Cellar/python/3.7.3/Frameworks/Python.framework/Versions/3.7/lib/python3.7/traceback.py'>
2019-07-19 14:22:22,518 - DEBUG - Starting new HTTP connection (1): localhost:8801
2019-07-19 14:22:22,518 - WARNING - Unable To Push Package To DB.
Exception: HTTPConnectionPool(host='localhost', port=8801): Max retries exceeded with url: /device/dataPush (Caused by NewConnectionError('<urllib3.connection.HTTPConnection object at 0x10708e5f8>: Failed to establish a new connection: [Errno 61] Connection refused'))
TraceBack: <module 'traceback' from '/usr/local/Cellar/python/3.7.3/Frameworks/Python.framework/Versions/3.7/lib/python3.7/traceback.py'>
2019-07-19 14:22:22,520 - DEBUG - Starting new HTTP connection (1): localhost:8801
2019-07-19 14:22:22,521 - WARNING - Unable To Push Package To DB.
Exception: HTTPConnectionPool(host='localhost', port=8801): Max retries exceeded with url: /device/dataPush (Caused by NewConnectionError('<urllib3.connection.HTTPConnection object at 0x10708ecc0>: Failed to establish a new connection: [Errno 61] Connection refused'))
TraceBack: <module 'traceback' from '/usr/local/Cellar/python/3.7.3/Frameworks/Python.framework/Versions/3.7/lib/python3.7/traceback.py'>
2019-07-19 14:22:22,522 - DEBUG - Starting new HTTP connection (1): localhost:8801
2019-07-19 14:22:22,523 - WARNING - Unable To Push Package To DB.
Exception: HTTPConnectionPool(host='localhost', port=8801): Max retries exceeded with url: /device/dataPush (Caused by NewConnectionError('<urllib3.connection.HTTPConnection object at 0x106390c50>: Failed to establish a new connection: [Errno 61] Connection refused'))
TraceBack: <module 'traceback' from '/usr/local/Cellar/python/3.7.3/Frameworks/Python.framework/Versions/3.7/lib/python3.7/traceback.py'>
2019-07-19 14:22:22,525 - DEBUG - Starting new HTTP connection (1): localhost:8801
2019-07-19 14:22:22,525 - WARNING - Unable To Push Package To DB.
Exception: HTTPConnectionPool(host='localhost', port=8801): Max retries exceeded with url: /device/dataPush (Caused by NewConnectionError('<urllib3.connection.HTTPConnection object at 0x1063907b8>: Failed to establish a new connection: [Errno 61] Connection refused'))
TraceBack: <module 'traceback' from '/usr/local/Cellar/python/3.7.3/Frameworks/Python.framework/Versions/3.7/lib/python3.7/traceback.py'>
2019-07-19 14:22:22,527 - DEBUG - Starting new HTTP connection (1): localhost:8801
2019-07-19 14:22:22,527 - WARNING - Unable To Push Package To DB.
Exception: HTTPConnectionPool(host='localhost', port=8801): Max retries exceeded with url: /device/dataPush (Caused by NewConnectionError('<urllib3.connection.HTTPConnection object at 0x106368898>: Failed to establish a new connection: [Errno 61] Connection refused'))
TraceBack: <module 'traceback' from '/usr/local/Cellar/python/3.7.3/Frameworks/Python.framework/Versions/3.7/lib/python3.7/traceback.py'>
